<?xml version="1.0"?>
<!--
  EasyTrainer Dual-Arm Test — URDF  (single dual_arm robot, dual-EE IK)
  =====================================================================
  Kinematic counterpart of assets/dual_arm_scene.xml. Used by the Pinocchio
  IK solver for the role='dual_arm' robot. CRITICAL ORDERING CONTRACT:

    The IK reduced model preserves URDF joint-declaration order. agent.py
    splits the solved vector at the midpoint (half = len//2) into left/right.
    Therefore ALL six left-arm joints MUST be declared BEFORE all six
    right-arm joints. The four gripper joints are locked out (joints_to_lock),
    so the reduced model is exactly 12 DOF -> [L1..L6, R1..R6].

  Each arm mirrors urdf/tutorial_arm.urdf; the only differences are the
  left_/right_ name prefixes and the base y-offset baked into joint1's origin
  (+0.15 left, -0.15 right) so FK matches the MJCF base placement.

  EE sites: gripper_base + (0.05,0,0) == link6 frame + (0.095,0,0).
            ik_setting parent = left_joint6 / right_joint6, offset=[0.095,0,0].
-->
<robot name="dual_arm">

  <link name="base_link">
    <inertial>
      <mass value="2.0"/>
      <origin xyz="0 0 0.05" rpy="0 0 0"/>
      <inertia ixx="0.005" iyy="0.005" izz="0.004" ixy="0" ixz="0" iyz="0"/>
    </inertial>
  </link>

  <!-- ======================= LEFT ARM (declared first) ================= -->
  <link name="left_link1">
    <inertial><mass value="0.5"/><origin xyz="0 0 0.05" rpy="0 0 0"/>
      <inertia ixx="0.002" iyy="0.002" izz="0.0005" ixy="0" ixz="0" iyz="0"/></inertial>
  </link>
  <joint name="left_joint1" type="revolute">
    <origin xyz="0 0.15 0.10" rpy="0 0 0"/>
    <parent link="base_link"/><child link="left_link1"/>
    <axis xyz="0 0 1"/><limit lower="-3.14" upper="3.14" effort="100" velocity="5"/>
  </joint>

  <link name="left_link2">
    <inertial><mass value="0.5"/><origin xyz="0.10 0 0" rpy="0 0 0"/>
      <inertia ixx="0.0005" iyy="0.005" izz="0.005" ixy="0" ixz="0" iyz="0"/></inertial>
  </link>
  <joint name="left_joint2" type="revolute">
    <origin xyz="0 0 0.10" rpy="0 0 0"/>
    <parent link="left_link1"/><child link="left_link2"/>
    <axis xyz="0 -1 0"/><limit lower="-1.57" upper="1.57" effort="100" velocity="5"/>
  </joint>

  <link name="left_link3">
    <inertial><mass value="0.5"/><origin xyz="0.09 0 0" rpy="0 0 0"/>
      <inertia ixx="0.0004" iyy="0.004" izz="0.004" ixy="0" ixz="0" iyz="0"/></inertial>
  </link>
  <joint name="left_joint3" type="revolute">
    <origin xyz="0.20 0 0" rpy="0 0 0"/>
    <parent link="left_link2"/><child link="left_link3"/>
    <axis xyz="0 -1 0"/><limit lower="-2.40" upper="0.50" effort="100" velocity="5"/>
  </joint>

  <link name="left_link4">
    <inertial><mass value="0.5"/><origin xyz="0.04 0 0" rpy="0 0 0"/>
      <inertia ixx="0.0003" iyy="0.001" izz="0.001" ixy="0" ixz="0" iyz="0"/></inertial>
  </link>
  <joint name="left_joint4" type="revolute">
    <origin xyz="0.18 0 0" rpy="0 0 0"/>
    <parent link="left_link3"/><child link="left_link4"/>
    <axis xyz="1 0 0"/><limit lower="-3.14" upper="3.14" effort="100" velocity="5"/>
  </joint>

  <link name="left_link5">
    <inertial><mass value="0.5"/><origin xyz="0.03 0 0" rpy="0 0 0"/>
      <inertia ixx="0.0002" iyy="0.0008" izz="0.0008" ixy="0" ixz="0" iyz="0"/></inertial>
  </link>
  <joint name="left_joint5" type="revolute">
    <origin xyz="0.08 0 0" rpy="0 0 0"/>
    <parent link="left_link4"/><child link="left_link5"/>
    <axis xyz="0 -1 0"/><limit lower="-1.40" upper="1.40" effort="100" velocity="5"/>
  </joint>

  <link name="left_link6">
    <inertial><mass value="0.2"/><origin xyz="0.020 0 0" rpy="0 0 0"/>
      <inertia ixx="0.0001" iyy="0.0002" izz="0.0002" ixy="0" ixz="0" iyz="0"/></inertial>
  </link>
  <joint name="left_joint6" type="revolute">
    <origin xyz="0.06 0 0" rpy="0 0 0"/>
    <parent link="left_link5"/><child link="left_link6"/>
    <axis xyz="1 0 0"/><limit lower="-3.14" upper="3.14" effort="100" velocity="5"/>
  </joint>

  <link name="left_gripper_base">
    <inertial><mass value="0.1"/><origin xyz="0 0 0" rpy="0 0 0"/>
      <inertia ixx="0.00005" iyy="0.00003" izz="0.00006" ixy="0" ixz="0" iyz="0"/></inertial>
  </link>
  <joint name="left_joint_gripper_base" type="fixed">
    <origin xyz="0.045 0 0" rpy="0 0 0"/>
    <parent link="left_link6"/><child link="left_gripper_base"/>
  </joint>

  <link name="left_finger_left">
    <inertial><mass value="0.03"/><origin xyz="0 0 0" rpy="0 0 0"/>
      <inertia ixx="0.00001" iyy="0.00001" izz="0.000005" ixy="0" ixz="0" iyz="0"/></inertial>
  </link>
  <joint name="left_gripper" type="prismatic">
    <origin xyz="0.030 0.018 0" rpy="0 0 0"/>
    <parent link="left_gripper_base"/><child link="left_finger_left"/>
    <axis xyz="0 1 0"/><limit lower="0" upper="0.04" effort="50" velocity="0.5"/>
  </joint>

  <link name="left_finger_right">
    <inertial><mass value="0.03"/><origin xyz="0 0 0" rpy="0 0 0"/>
      <inertia ixx="0.00001" iyy="0.00001" izz="0.000005" ixy="0" ixz="0" iyz="0"/></inertial>
  </link>
  <joint name="left_gripper_mirror" type="prismatic">
    <origin xyz="0.030 -0.018 0" rpy="0 0 0"/>
    <parent link="left_gripper_base"/><child link="left_finger_right"/>
    <axis xyz="0 -1 0"/><limit lower="0" upper="0.04" effort="50" velocity="0.5"/>
  </joint>

  <!-- ======================= RIGHT ARM (declared second) ============== -->
  <link name="right_link1">
    <inertial><mass value="0.5"/><origin xyz="0 0 0.05" rpy="0 0 0"/>
      <inertia ixx="0.002" iyy="0.002" izz="0.0005" ixy="0" ixz="0" iyz="0"/></inertial>
  </link>
  <joint name="right_joint1" type="revolute">
    <origin xyz="0 -0.15 0.10" rpy="0 0 0"/>
    <parent link="base_link"/><child link="right_link1"/>
    <axis xyz="0 0 1"/><limit lower="-3.14" upper="3.14" effort="100" velocity="5"/>
  </joint>

  <link name="right_link2">
    <inertial><mass value="0.5"/><origin xyz="0.10 0 0" rpy="0 0 0"/>
      <inertia ixx="0.0005" iyy="0.005" izz="0.005" ixy="0" ixz="0" iyz="0"/></inertial>
  </link>
  <joint name="right_joint2" type="revolute">
    <origin xyz="0 0 0.10" rpy="0 0 0"/>
    <parent link="right_link1"/><child link="right_link2"/>
    <axis xyz="0 -1 0"/><limit lower="-1.57" upper="1.57" effort="100" velocity="5"/>
  </joint>

  <link name="right_link3">
    <inertial><mass value="0.5"/><origin xyz="0.09 0 0" rpy="0 0 0"/>
      <inertia ixx="0.0004" iyy="0.004" izz="0.004" ixy="0" ixz="0" iyz="0"/></inertial>
  </link>
  <joint name="right_joint3" type="revolute">
    <origin xyz="0.20 0 0" rpy="0 0 0"/>
    <parent link="right_link2"/><child link="right_link3"/>
    <axis xyz="0 -1 0"/><limit lower="-2.40" upper="0.50" effort="100" velocity="5"/>
  </joint>

  <link name="right_link4">
    <inertial><mass value="0.5"/><origin xyz="0.04 0 0" rpy="0 0 0"/>
      <inertia ixx="0.0003" iyy="0.001" izz="0.001" ixy="0" ixz="0" iyz="0"/></inertial>
  </link>
  <joint name="right_joint4" type="revolute">
    <origin xyz="0.18 0 0" rpy="0 0 0"/>
    <parent link="right_link3"/><child link="right_link4"/>
    <axis xyz="1 0 0"/><limit lower="-3.14" upper="3.14" effort="100" velocity="5"/>
  </joint>

  <link name="right_link5">
    <inertial><mass value="0.5"/><origin xyz="0.03 0 0" rpy="0 0 0"/>
      <inertia ixx="0.0002" iyy="0.0008" izz="0.0008" ixy="0" ixz="0" iyz="0"/></inertial>
  </link>
  <joint name="right_joint5" type="revolute">
    <origin xyz="0.08 0 0" rpy="0 0 0"/>
    <parent link="right_link4"/><child link="right_link5"/>
    <axis xyz="0 -1 0"/><limit lower="-1.40" upper="1.40" effort="100" velocity="5"/>
  </joint>

  <link name="right_link6">
    <inertial><mass value="0.2"/><origin xyz="0.020 0 0" rpy="0 0 0"/>
      <inertia ixx="0.0001" iyy="0.0002" izz="0.0002" ixy="0" ixz="0" iyz="0"/></inertial>
  </link>
  <joint name="right_joint6" type="revolute">
    <origin xyz="0.06 0 0" rpy="0 0 0"/>
    <parent link="right_link5"/><child link="right_link6"/>
    <axis xyz="1 0 0"/><limit lower="-3.14" upper="3.14" effort="100" velocity="5"/>
  </joint>

  <link name="right_gripper_base">
    <inertial><mass value="0.1"/><origin xyz="0 0 0" rpy="0 0 0"/>
      <inertia ixx="0.00005" iyy="0.00003" izz="0.00006" ixy="0" ixz="0" iyz="0"/></inertial>
  </link>
  <joint name="right_joint_gripper_base" type="fixed">
    <origin xyz="0.045 0 0" rpy="0 0 0"/>
    <parent link="right_link6"/><child link="right_gripper_base"/>
  </joint>

  <link name="right_finger_left">
    <inertial><mass value="0.03"/><origin xyz="0 0 0" rpy="0 0 0"/>
      <inertia ixx="0.00001" iyy="0.00001" izz="0.000005" ixy="0" ixz="0" iyz="0"/></inertial>
  </link>
  <joint name="right_gripper" type="prismatic">
    <origin xyz="0.030 0.018 0" rpy="0 0 0"/>
    <parent link="right_gripper_base"/><child link="right_finger_left"/>
    <axis xyz="0 1 0"/><limit lower="0" upper="0.04" effort="50" velocity="0.5"/>
  </joint>

  <link name="right_finger_right">
    <inertial><mass value="0.03"/><origin xyz="0 0 0" rpy="0 0 0"/>
      <inertia ixx="0.00001" iyy="0.00001" izz="0.000005" ixy="0" ixz="0" iyz="0"/></inertial>
  </link>
  <joint name="right_gripper_mirror" type="prismatic">
    <origin xyz="0.030 -0.018 0" rpy="0 0 0"/>
    <parent link="right_gripper_base"/><child link="right_finger_right"/>
    <axis xyz="0 -1 0"/><limit lower="0" upper="0.04" effort="50" velocity="0.5"/>
  </joint>

</robot>
